[02/Jun/2021 23:07:29] ERROR [django.request:224] Internal Server Error: /info/60945ef77125b2efbf41a9e2/
Traceback (most recent call last):
  File "/usr/local/lib/python3.9/site-packages/django/core/handlers/exception.py", line 47, in inner
    response = get_response(request)
  File "/usr/local/lib/python3.9/site-packages/django/core/handlers/base.py", line 181, in _get_response
    response = wrapped_callback(request, *callback_args, **callback_kwargs)
  File "/code/senderos/views.py", line 52, in info
    e = Excursión.objects.get(id=id)
  File "/usr/local/lib/python3.9/site-packages/mongoengine/queryset/base.py", line 266, in get
    result = next(queryset)
  File "/usr/local/lib/python3.9/site-packages/mongoengine/queryset/base.py", line 1577, in __next__
    doc = self._document._from_son(
  File "/usr/local/lib/python3.9/site-packages/mongoengine/base/document.py", line 805, in _from_son
    raise InvalidDocumentError(msg)
mongoengine.errors.InvalidDocumentError: Invalid data to create a `Excursión` instance.
Field 'comentarios' - The source SON object needs to be of type 'dict' but a '<class 'str'>' was found
[02/Jun/2021 23:07:29] ERROR [django.request:224] Internal Server Error: /info/60945ef77125b2efbf41a9e2/
Traceback (most recent call last):
  File "/usr/local/lib/python3.9/site-packages/django/core/handlers/exception.py", line 47, in inner
    response = get_response(request)
  File "/usr/local/lib/python3.9/site-packages/django/core/handlers/base.py", line 181, in _get_response
    response = wrapped_callback(request, *callback_args, **callback_kwargs)
  File "/code/senderos/views.py", line 52, in info
    e = Excursión.objects.get(id=id)
  File "/usr/local/lib/python3.9/site-packages/mongoengine/queryset/base.py", line 266, in get
    result = next(queryset)
  File "/usr/local/lib/python3.9/site-packages/mongoengine/queryset/base.py", line 1577, in __next__
    doc = self._document._from_son(
  File "/usr/local/lib/python3.9/site-packages/mongoengine/base/document.py", line 805, in _from_son
    raise InvalidDocumentError(msg)
mongoengine.errors.InvalidDocumentError: Invalid data to create a `Excursión` instance.
Field 'comentarios' - The source SON object needs to be of type 'dict' but a '<class 'str'>' was found
[02/Jun/2021 23:07:29] ERROR [django.server:161] "GET /info/60945ef77125b2efbf41a9e2/? HTTP/1.1" 500 79564
[02/Jun/2021 23:07:29] ERROR [django.server:161] "GET /info/60945ef77125b2efbf41a9e2/? HTTP/1.1" 500 79564
[02/Jun/2021 23:10:04] ERROR [django.request:224] Internal Server Error: /cambiarlikes/60945ef77125b2efbf41a9e2
Traceback (most recent call last):
  File "/usr/local/lib/python3.9/site-packages/django/core/handlers/exception.py", line 47, in inner
    response = get_response(request)
  File "/usr/local/lib/python3.9/site-packages/django/core/handlers/base.py", line 181, in _get_response
    response = wrapped_callback(request, *callback_args, **callback_kwargs)
  File "/code/senderos/views.py", line 200, in cambiarlikes
    e.save()
  File "/usr/local/lib/python3.9/site-packages/mongoengine/document.py", line 387, in save
    self.validate(clean=clean)
  File "/usr/local/lib/python3.9/site-packages/mongoengine/base/document.py", line 432, in validate
    raise ValidationError(message, errors=errors)
mongoengine.errors.ValidationError: ValidationError (Excursión:60945ef77125b2efbf41a9e2) (fecha.cannot parse date "26-02-12": ['comentarios'])
[02/Jun/2021 23:10:04] ERROR [django.request:224] Internal Server Error: /cambiarlikes/60945ef77125b2efbf41a9e2
Traceback (most recent call last):
  File "/usr/local/lib/python3.9/site-packages/django/core/handlers/exception.py", line 47, in inner
    response = get_response(request)
  File "/usr/local/lib/python3.9/site-packages/django/core/handlers/base.py", line 181, in _get_response
    response = wrapped_callback(request, *callback_args, **callback_kwargs)
  File "/code/senderos/views.py", line 200, in cambiarlikes
    e.save()
  File "/usr/local/lib/python3.9/site-packages/mongoengine/document.py", line 387, in save
    self.validate(clean=clean)
  File "/usr/local/lib/python3.9/site-packages/mongoengine/base/document.py", line 432, in validate
    raise ValidationError(message, errors=errors)
mongoengine.errors.ValidationError: ValidationError (Excursión:60945ef77125b2efbf41a9e2) (fecha.cannot parse date "26-02-12": ['comentarios'])
[02/Jun/2021 23:10:04] ERROR [django.server:161] "GET /cambiarlikes/60945ef77125b2efbf41a9e2?subir=true HTTP/1.1" 500 74266
[02/Jun/2021 23:10:04] ERROR [django.server:161] "GET /cambiarlikes/60945ef77125b2efbf41a9e2?subir=true HTTP/1.1" 500 74266
[02/Jun/2021 23:10:07] ERROR [django.request:224] Internal Server Error: /cambiarlikes/60945ef77125b2efbf41a9e2
Traceback (most recent call last):
  File "/usr/local/lib/python3.9/site-packages/django/core/handlers/exception.py", line 47, in inner
    response = get_response(request)
  File "/usr/local/lib/python3.9/site-packages/django/core/handlers/base.py", line 181, in _get_response
    response = wrapped_callback(request, *callback_args, **callback_kwargs)
  File "/code/senderos/views.py", line 200, in cambiarlikes
    e.save()
  File "/usr/local/lib/python3.9/site-packages/mongoengine/document.py", line 387, in save
    self.validate(clean=clean)
  File "/usr/local/lib/python3.9/site-packages/mongoengine/base/document.py", line 432, in validate
    raise ValidationError(message, errors=errors)
mongoengine.errors.ValidationError: ValidationError (Excursión:60945ef77125b2efbf41a9e2) (fecha.cannot parse date "26-02-12": ['comentarios'])
[02/Jun/2021 23:10:07] ERROR [django.request:224] Internal Server Error: /cambiarlikes/60945ef77125b2efbf41a9e2
Traceback (most recent call last):
  File "/usr/local/lib/python3.9/site-packages/django/core/handlers/exception.py", line 47, in inner
    response = get_response(request)
  File "/usr/local/lib/python3.9/site-packages/django/core/handlers/base.py", line 181, in _get_response
    response = wrapped_callback(request, *callback_args, **callback_kwargs)
  File "/code/senderos/views.py", line 200, in cambiarlikes
    e.save()
  File "/usr/local/lib/python3.9/site-packages/mongoengine/document.py", line 387, in save
    self.validate(clean=clean)
  File "/usr/local/lib/python3.9/site-packages/mongoengine/base/document.py", line 432, in validate
    raise ValidationError(message, errors=errors)
mongoengine.errors.ValidationError: ValidationError (Excursión:60945ef77125b2efbf41a9e2) (fecha.cannot parse date "26-02-12": ['comentarios'])
[02/Jun/2021 23:10:07] ERROR [django.server:161] "GET /cambiarlikes/60945ef77125b2efbf41a9e2?subir=false HTTP/1.1" 500 74275
[02/Jun/2021 23:10:07] ERROR [django.server:161] "GET /cambiarlikes/60945ef77125b2efbf41a9e2?subir=false HTTP/1.1" 500 74275
[02/Jun/2021 23:10:10] ERROR [django.request:224] Internal Server Error: /cambiarlikes/60945ef77125b2efbf41a9e2
Traceback (most recent call last):
  File "/usr/local/lib/python3.9/site-packages/django/core/handlers/exception.py", line 47, in inner
    response = get_response(request)
  File "/usr/local/lib/python3.9/site-packages/django/core/handlers/base.py", line 181, in _get_response
    response = wrapped_callback(request, *callback_args, **callback_kwargs)
  File "/code/senderos/views.py", line 200, in cambiarlikes
    e.save()
  File "/usr/local/lib/python3.9/site-packages/mongoengine/document.py", line 387, in save
    self.validate(clean=clean)
  File "/usr/local/lib/python3.9/site-packages/mongoengine/base/document.py", line 432, in validate
    raise ValidationError(message, errors=errors)
mongoengine.errors.ValidationError: ValidationError (Excursión:60945ef77125b2efbf41a9e2) (fecha.cannot parse date "26-02-12": ['comentarios'])
[02/Jun/2021 23:10:10] ERROR [django.request:224] Internal Server Error: /cambiarlikes/60945ef77125b2efbf41a9e2
Traceback (most recent call last):
  File "/usr/local/lib/python3.9/site-packages/django/core/handlers/exception.py", line 47, in inner
    response = get_response(request)
  File "/usr/local/lib/python3.9/site-packages/django/core/handlers/base.py", line 181, in _get_response
    response = wrapped_callback(request, *callback_args, **callback_kwargs)
  File "/code/senderos/views.py", line 200, in cambiarlikes
    e.save()
  File "/usr/local/lib/python3.9/site-packages/mongoengine/document.py", line 387, in save
    self.validate(clean=clean)
  File "/usr/local/lib/python3.9/site-packages/mongoengine/base/document.py", line 432, in validate
    raise ValidationError(message, errors=errors)
mongoengine.errors.ValidationError: ValidationError (Excursión:60945ef77125b2efbf41a9e2) (fecha.cannot parse date "26-02-12": ['comentarios'])
[02/Jun/2021 23:10:10] ERROR [django.server:161] "GET /cambiarlikes/60945ef77125b2efbf41a9e2?subir=true HTTP/1.1" 500 74266
[02/Jun/2021 23:10:10] ERROR [django.server:161] "GET /cambiarlikes/60945ef77125b2efbf41a9e2?subir=true HTTP/1.1" 500 74266
[02/Jun/2021 23:10:18] ERROR [django.request:224] Internal Server Error: /cambiarlikes/60945ef77125b2efbf41a9e2
Traceback (most recent call last):
  File "/usr/local/lib/python3.9/site-packages/django/core/handlers/exception.py", line 47, in inner
    response = get_response(request)
  File "/usr/local/lib/python3.9/site-packages/django/core/handlers/base.py", line 181, in _get_response
    response = wrapped_callback(request, *callback_args, **callback_kwargs)
  File "/code/senderos/views.py", line 200, in cambiarlikes
    e.save()
  File "/usr/local/lib/python3.9/site-packages/mongoengine/document.py", line 387, in save
    self.validate(clean=clean)
  File "/usr/local/lib/python3.9/site-packages/mongoengine/base/document.py", line 432, in validate
    raise ValidationError(message, errors=errors)
mongoengine.errors.ValidationError: ValidationError (Excursión:60945ef77125b2efbf41a9e2) (fecha.cannot parse date "26-02-12": ['comentarios'])
[02/Jun/2021 23:10:18] ERROR [django.request:224] Internal Server Error: /cambiarlikes/60945ef77125b2efbf41a9e2
Traceback (most recent call last):
  File "/usr/local/lib/python3.9/site-packages/django/core/handlers/exception.py", line 47, in inner
    response = get_response(request)
  File "/usr/local/lib/python3.9/site-packages/django/core/handlers/base.py", line 181, in _get_response
    response = wrapped_callback(request, *callback_args, **callback_kwargs)
  File "/code/senderos/views.py", line 200, in cambiarlikes
    e.save()
  File "/usr/local/lib/python3.9/site-packages/mongoengine/document.py", line 387, in save
    self.validate(clean=clean)
  File "/usr/local/lib/python3.9/site-packages/mongoengine/base/document.py", line 432, in validate
    raise ValidationError(message, errors=errors)
mongoengine.errors.ValidationError: ValidationError (Excursión:60945ef77125b2efbf41a9e2) (fecha.cannot parse date "26-02-12": ['comentarios'])
[02/Jun/2021 23:10:18] ERROR [django.server:161] "GET /cambiarlikes/60945ef77125b2efbf41a9e2?subir=true HTTP/1.1" 500 74266
[02/Jun/2021 23:10:18] ERROR [django.server:161] "GET /cambiarlikes/60945ef77125b2efbf41a9e2?subir=true HTTP/1.1" 500 74266
[02/Jun/2021 23:11:21] ERROR [django.request:224] Internal Server Error: /cambiarlikes/60945ef77125b2efbf41a9e2
Traceback (most recent call last):
  File "/usr/local/lib/python3.9/site-packages/django/core/handlers/exception.py", line 47, in inner
    response = get_response(request)
  File "/usr/local/lib/python3.9/site-packages/django/core/handlers/base.py", line 181, in _get_response
    response = wrapped_callback(request, *callback_args, **callback_kwargs)
  File "/code/senderos/views.py", line 200, in cambiarlikes
    e.save()
  File "/usr/local/lib/python3.9/site-packages/mongoengine/document.py", line 387, in save
    self.validate(clean=clean)
  File "/usr/local/lib/python3.9/site-packages/mongoengine/base/document.py", line 432, in validate
    raise ValidationError(message, errors=errors)
mongoengine.errors.ValidationError: ValidationError (Excursión:60945ef77125b2efbf41a9e2) (fecha.cannot parse date "26-02-12": ['comentarios'])
[02/Jun/2021 23:11:21] ERROR [django.request:224] Internal Server Error: /cambiarlikes/60945ef77125b2efbf41a9e2
Traceback (most recent call last):
  File "/usr/local/lib/python3.9/site-packages/django/core/handlers/exception.py", line 47, in inner
    response = get_response(request)
  File "/usr/local/lib/python3.9/site-packages/django/core/handlers/base.py", line 181, in _get_response
    response = wrapped_callback(request, *callback_args, **callback_kwargs)
  File "/code/senderos/views.py", line 200, in cambiarlikes
    e.save()
  File "/usr/local/lib/python3.9/site-packages/mongoengine/document.py", line 387, in save
    self.validate(clean=clean)
  File "/usr/local/lib/python3.9/site-packages/mongoengine/base/document.py", line 432, in validate
    raise ValidationError(message, errors=errors)
mongoengine.errors.ValidationError: ValidationError (Excursión:60945ef77125b2efbf41a9e2) (fecha.cannot parse date "26-02-12": ['comentarios'])
[02/Jun/2021 23:11:21] ERROR [django.server:161] "GET /cambiarlikes/60945ef77125b2efbf41a9e2?subir=true HTTP/1.1" 500 74266
[02/Jun/2021 23:11:21] ERROR [django.server:161] "GET /cambiarlikes/60945ef77125b2efbf41a9e2?subir=true HTTP/1.1" 500 74266
[02/Jun/2021 23:13:09] ERROR [django.request:224] Internal Server Error: /cambiarlikes/60945ef77125b2efbf41a9e2
Traceback (most recent call last):
  File "/usr/local/lib/python3.9/site-packages/django/core/handlers/exception.py", line 47, in inner
    response = get_response(request)
  File "/usr/local/lib/python3.9/site-packages/django/core/handlers/base.py", line 181, in _get_response
    response = wrapped_callback(request, *callback_args, **callback_kwargs)
  File "/code/senderos/views.py", line 200, in cambiarlikes
    e.save()
  File "/usr/local/lib/python3.9/site-packages/mongoengine/document.py", line 387, in save
    self.validate(clean=clean)
  File "/usr/local/lib/python3.9/site-packages/mongoengine/base/document.py", line 432, in validate
    raise ValidationError(message, errors=errors)
mongoengine.errors.ValidationError: ValidationError (Excursión:60945ef77125b2efbf41a9e2) (fecha.cannot parse date "2015-06-25 T 00:00:00.000 Z": ['comentarios'])
[02/Jun/2021 23:13:09] ERROR [django.request:224] Internal Server Error: /cambiarlikes/60945ef77125b2efbf41a9e2
Traceback (most recent call last):
  File "/usr/local/lib/python3.9/site-packages/django/core/handlers/exception.py", line 47, in inner
    response = get_response(request)
  File "/usr/local/lib/python3.9/site-packages/django/core/handlers/base.py", line 181, in _get_response
    response = wrapped_callback(request, *callback_args, **callback_kwargs)
  File "/code/senderos/views.py", line 200, in cambiarlikes
    e.save()
  File "/usr/local/lib/python3.9/site-packages/mongoengine/document.py", line 387, in save
    self.validate(clean=clean)
  File "/usr/local/lib/python3.9/site-packages/mongoengine/base/document.py", line 432, in validate
    raise ValidationError(message, errors=errors)
mongoengine.errors.ValidationError: ValidationError (Excursión:60945ef77125b2efbf41a9e2) (fecha.cannot parse date "2015-06-25 T 00:00:00.000 Z": ['comentarios'])
[02/Jun/2021 23:13:09] ERROR [django.server:161] "GET /cambiarlikes/60945ef77125b2efbf41a9e2?subir=true HTTP/1.1" 500 74361
[02/Jun/2021 23:13:09] ERROR [django.server:161] "GET /cambiarlikes/60945ef77125b2efbf41a9e2?subir=true HTTP/1.1" 500 74361
[02/Jun/2021 23:13:49] ERROR [django.request:224] Internal Server Error: /cambiarlikes/60945ef77125b2efbf41a9e2
Traceback (most recent call last):
  File "/usr/local/lib/python3.9/site-packages/django/core/handlers/exception.py", line 47, in inner
    response = get_response(request)
  File "/usr/local/lib/python3.9/site-packages/django/core/handlers/base.py", line 181, in _get_response
    response = wrapped_callback(request, *callback_args, **callback_kwargs)
  File "/code/senderos/views.py", line 200, in cambiarlikes
    e.save()
  File "/usr/local/lib/python3.9/site-packages/mongoengine/document.py", line 387, in save
    self.validate(clean=clean)
  File "/usr/local/lib/python3.9/site-packages/mongoengine/base/document.py", line 432, in validate
    raise ValidationError(message, errors=errors)
mongoengine.errors.ValidationError: ValidationError (Excursión:60945ef77125b2efbf41a9e2) (fecha.cannot parse date "": ['comentarios'])
[02/Jun/2021 23:13:49] ERROR [django.request:224] Internal Server Error: /cambiarlikes/60945ef77125b2efbf41a9e2
Traceback (most recent call last):
  File "/usr/local/lib/python3.9/site-packages/django/core/handlers/exception.py", line 47, in inner
    response = get_response(request)
  File "/usr/local/lib/python3.9/site-packages/django/core/handlers/base.py", line 181, in _get_response
    response = wrapped_callback(request, *callback_args, **callback_kwargs)
  File "/code/senderos/views.py", line 200, in cambiarlikes
    e.save()
  File "/usr/local/lib/python3.9/site-packages/mongoengine/document.py", line 387, in save
    self.validate(clean=clean)
  File "/usr/local/lib/python3.9/site-packages/mongoengine/base/document.py", line 432, in validate
    raise ValidationError(message, errors=errors)
mongoengine.errors.ValidationError: ValidationError (Excursión:60945ef77125b2efbf41a9e2) (fecha.cannot parse date "": ['comentarios'])
[02/Jun/2021 23:13:49] ERROR [django.server:161] "GET /cambiarlikes/60945ef77125b2efbf41a9e2?subir=true HTTP/1.1" 500 74226
[02/Jun/2021 23:13:49] ERROR [django.server:161] "GET /cambiarlikes/60945ef77125b2efbf41a9e2?subir=true HTTP/1.1" 500 74226
[02/Jun/2021 23:14:37] ERROR [django.request:224] Internal Server Error: /cambiarlikes/60945ef77125b2efbf41a9e2
Traceback (most recent call last):
  File "/usr/local/lib/python3.9/site-packages/django/core/handlers/exception.py", line 47, in inner
    response = get_response(request)
  File "/usr/local/lib/python3.9/site-packages/django/core/handlers/base.py", line 181, in _get_response
    response = wrapped_callback(request, *callback_args, **callback_kwargs)
  File "/code/senderos/views.py", line 200, in cambiarlikes
    e.save()
  File "/usr/local/lib/python3.9/site-packages/mongoengine/document.py", line 387, in save
    self.validate(clean=clean)
  File "/usr/local/lib/python3.9/site-packages/mongoengine/base/document.py", line 432, in validate
    raise ValidationError(message, errors=errors)
mongoengine.errors.ValidationError: ValidationError (Excursión:60945ef77125b2efbf41a9e2) (fecha.cannot parse date "1595784271766.0": ['comentarios'])
[02/Jun/2021 23:14:37] ERROR [django.request:224] Internal Server Error: /cambiarlikes/60945ef77125b2efbf41a9e2
Traceback (most recent call last):
  File "/usr/local/lib/python3.9/site-packages/django/core/handlers/exception.py", line 47, in inner
    response = get_response(request)
  File "/usr/local/lib/python3.9/site-packages/django/core/handlers/base.py", line 181, in _get_response
    response = wrapped_callback(request, *callback_args, **callback_kwargs)
  File "/code/senderos/views.py", line 200, in cambiarlikes
    e.save()
  File "/usr/local/lib/python3.9/site-packages/mongoengine/document.py", line 387, in save
    self.validate(clean=clean)
  File "/usr/local/lib/python3.9/site-packages/mongoengine/base/document.py", line 432, in validate
    raise ValidationError(message, errors=errors)
mongoengine.errors.ValidationError: ValidationError (Excursión:60945ef77125b2efbf41a9e2) (fecha.cannot parse date "1595784271766.0": ['comentarios'])
[02/Jun/2021 23:14:37] ERROR [django.server:161] "GET /cambiarlikes/60945ef77125b2efbf41a9e2?subir=true HTTP/1.1" 500 74301
[02/Jun/2021 23:14:37] ERROR [django.server:161] "GET /cambiarlikes/60945ef77125b2efbf41a9e2?subir=true HTTP/1.1" 500 74301
