[15/Apr/2021 10:49:26] ERROR [django.request:224] Internal Server Error: /accounts/login/
Traceback (most recent call last):
  File "/usr/local/lib/python3.9/site-packages/django/db/backends/utils.py", line 84, in _execute
    return self.cursor.execute(sql, params)
  File "/usr/local/lib/python3.9/site-packages/django/db/backends/sqlite3/base.py", line 423, in execute
    return Database.Cursor.execute(self, query, params)
sqlite3.OperationalError: no such table: django_site

The above exception was the direct cause of the following exception:

Traceback (most recent call last):
  File "/usr/local/lib/python3.9/site-packages/django/core/handlers/exception.py", line 47, in inner
    response = get_response(request)
  File "/usr/local/lib/python3.9/site-packages/django/core/handlers/base.py", line 181, in _get_response
    response = wrapped_callback(request, *callback_args, **callback_kwargs)
  File "/usr/local/lib/python3.9/site-packages/django/views/generic/base.py", line 70, in view
    return self.dispatch(request, *args, **kwargs)
  File "/usr/local/lib/python3.9/site-packages/django/utils/decorators.py", line 43, in _wrapper
    return bound_method(*args, **kwargs)
  File "/usr/local/lib/python3.9/site-packages/django/views/decorators/debug.py", line 89, in sensitive_post_parameters_wrapper
    return view(request, *args, **kwargs)
  File "/usr/local/lib/python3.9/site-packages/allauth/account/views.py", line 146, in dispatch
    return super(LoginView, self).dispatch(request, *args, **kwargs)
  File "/usr/local/lib/python3.9/site-packages/allauth/account/views.py", line 74, in dispatch
    response = super(RedirectAuthenticatedUserMixin, self).dispatch(
  File "/usr/local/lib/python3.9/site-packages/django/views/generic/base.py", line 98, in dispatch
    return handler(request, *args, **kwargs)
  File "/usr/local/lib/python3.9/site-packages/allauth/account/views.py", line 90, in get
    response = super(AjaxCapableProcessFormViewMixin, self).get(
  File "/usr/local/lib/python3.9/site-packages/django/views/generic/edit.py", line 133, in get
    return self.render_to_response(self.get_context_data())
  File "/usr/local/lib/python3.9/site-packages/allauth/account/views.py", line 177, in get_context_data
    site = get_current_site(self.request)
  File "/usr/local/lib/python3.9/site-packages/django/contrib/sites/shortcuts.py", line 13, in get_current_site
    return Site.objects.get_current(request)
  File "/usr/local/lib/python3.9/site-packages/django/contrib/sites/models.py", line 58, in get_current
    return self._get_site_by_id(site_id)
  File "/usr/local/lib/python3.9/site-packages/django/contrib/sites/models.py", line 30, in _get_site_by_id
    site = self.get(pk=site_id)
  File "/usr/local/lib/python3.9/site-packages/django/db/models/manager.py", line 85, in manager_method
    return getattr(self.get_queryset(), name)(*args, **kwargs)
  File "/usr/local/lib/python3.9/site-packages/django/db/models/query.py", line 431, in get
    num = len(clone)
  File "/usr/local/lib/python3.9/site-packages/django/db/models/query.py", line 262, in __len__
    self._fetch_all()
  File "/usr/local/lib/python3.9/site-packages/django/db/models/query.py", line 1324, in _fetch_all
    self._result_cache = list(self._iterable_class(self))
  File "/usr/local/lib/python3.9/site-packages/django/db/models/query.py", line 51, in __iter__
    results = compiler.execute_sql(chunked_fetch=self.chunked_fetch, chunk_size=self.chunk_size)
  File "/usr/local/lib/python3.9/site-packages/django/db/models/sql/compiler.py", line 1169, in execute_sql
    cursor.execute(sql, params)
  File "/usr/local/lib/python3.9/site-packages/django/db/backends/utils.py", line 98, in execute
    return super().execute(sql, params)
  File "/usr/local/lib/python3.9/site-packages/django/db/backends/utils.py", line 66, in execute
    return self._execute_with_wrappers(sql, params, many=False, executor=self._execute)
  File "/usr/local/lib/python3.9/site-packages/django/db/backends/utils.py", line 75, in _execute_with_wrappers
    return executor(sql, params, many, context)
  File "/usr/local/lib/python3.9/site-packages/django/db/backends/utils.py", line 84, in _execute
    return self.cursor.execute(sql, params)
  File "/usr/local/lib/python3.9/site-packages/django/db/utils.py", line 90, in __exit__
    raise dj_exc_value.with_traceback(traceback) from exc_value
  File "/usr/local/lib/python3.9/site-packages/django/db/backends/utils.py", line 84, in _execute
    return self.cursor.execute(sql, params)
  File "/usr/local/lib/python3.9/site-packages/django/db/backends/sqlite3/base.py", line 423, in execute
    return Database.Cursor.execute(self, query, params)
django.db.utils.OperationalError: no such table: django_site
[15/Apr/2021 10:49:26] ERROR [django.request:224] Internal Server Error: /accounts/login/
Traceback (most recent call last):
  File "/usr/local/lib/python3.9/site-packages/django/db/backends/utils.py", line 84, in _execute
    return self.cursor.execute(sql, params)
  File "/usr/local/lib/python3.9/site-packages/django/db/backends/sqlite3/base.py", line 423, in execute
    return Database.Cursor.execute(self, query, params)
sqlite3.OperationalError: no such table: django_site

The above exception was the direct cause of the following exception:

Traceback (most recent call last):
  File "/usr/local/lib/python3.9/site-packages/django/core/handlers/exception.py", line 47, in inner
    response = get_response(request)
  File "/usr/local/lib/python3.9/site-packages/django/core/handlers/base.py", line 181, in _get_response
    response = wrapped_callback(request, *callback_args, **callback_kwargs)
  File "/usr/local/lib/python3.9/site-packages/django/views/generic/base.py", line 70, in view
    return self.dispatch(request, *args, **kwargs)
  File "/usr/local/lib/python3.9/site-packages/django/utils/decorators.py", line 43, in _wrapper
    return bound_method(*args, **kwargs)
  File "/usr/local/lib/python3.9/site-packages/django/views/decorators/debug.py", line 89, in sensitive_post_parameters_wrapper
    return view(request, *args, **kwargs)
  File "/usr/local/lib/python3.9/site-packages/allauth/account/views.py", line 146, in dispatch
    return super(LoginView, self).dispatch(request, *args, **kwargs)
  File "/usr/local/lib/python3.9/site-packages/allauth/account/views.py", line 74, in dispatch
    response = super(RedirectAuthenticatedUserMixin, self).dispatch(
  File "/usr/local/lib/python3.9/site-packages/django/views/generic/base.py", line 98, in dispatch
    return handler(request, *args, **kwargs)
  File "/usr/local/lib/python3.9/site-packages/allauth/account/views.py", line 90, in get
    response = super(AjaxCapableProcessFormViewMixin, self).get(
  File "/usr/local/lib/python3.9/site-packages/django/views/generic/edit.py", line 133, in get
    return self.render_to_response(self.get_context_data())
  File "/usr/local/lib/python3.9/site-packages/allauth/account/views.py", line 177, in get_context_data
    site = get_current_site(self.request)
  File "/usr/local/lib/python3.9/site-packages/django/contrib/sites/shortcuts.py", line 13, in get_current_site
    return Site.objects.get_current(request)
  File "/usr/local/lib/python3.9/site-packages/django/contrib/sites/models.py", line 58, in get_current
    return self._get_site_by_id(site_id)
  File "/usr/local/lib/python3.9/site-packages/django/contrib/sites/models.py", line 30, in _get_site_by_id
    site = self.get(pk=site_id)
  File "/usr/local/lib/python3.9/site-packages/django/db/models/manager.py", line 85, in manager_method
    return getattr(self.get_queryset(), name)(*args, **kwargs)
  File "/usr/local/lib/python3.9/site-packages/django/db/models/query.py", line 431, in get
    num = len(clone)
  File "/usr/local/lib/python3.9/site-packages/django/db/models/query.py", line 262, in __len__
    self._fetch_all()
  File "/usr/local/lib/python3.9/site-packages/django/db/models/query.py", line 1324, in _fetch_all
    self._result_cache = list(self._iterable_class(self))
  File "/usr/local/lib/python3.9/site-packages/django/db/models/query.py", line 51, in __iter__
    results = compiler.execute_sql(chunked_fetch=self.chunked_fetch, chunk_size=self.chunk_size)
  File "/usr/local/lib/python3.9/site-packages/django/db/models/sql/compiler.py", line 1169, in execute_sql
    cursor.execute(sql, params)
  File "/usr/local/lib/python3.9/site-packages/django/db/backends/utils.py", line 98, in execute
    return super().execute(sql, params)
  File "/usr/local/lib/python3.9/site-packages/django/db/backends/utils.py", line 66, in execute
    return self._execute_with_wrappers(sql, params, many=False, executor=self._execute)
  File "/usr/local/lib/python3.9/site-packages/django/db/backends/utils.py", line 75, in _execute_with_wrappers
    return executor(sql, params, many, context)
  File "/usr/local/lib/python3.9/site-packages/django/db/backends/utils.py", line 84, in _execute
    return self.cursor.execute(sql, params)
  File "/usr/local/lib/python3.9/site-packages/django/db/utils.py", line 90, in __exit__
    raise dj_exc_value.with_traceback(traceback) from exc_value
  File "/usr/local/lib/python3.9/site-packages/django/db/backends/utils.py", line 84, in _execute
    return self.cursor.execute(sql, params)
  File "/usr/local/lib/python3.9/site-packages/django/db/backends/sqlite3/base.py", line 423, in execute
    return Database.Cursor.execute(self, query, params)
django.db.utils.OperationalError: no such table: django_site
[15/Apr/2021 10:49:26] ERROR [django.request:224] Internal Server Error: /accounts/login/
Traceback (most recent call last):
  File "/usr/local/lib/python3.9/site-packages/django/db/backends/utils.py", line 84, in _execute
    return self.cursor.execute(sql, params)
  File "/usr/local/lib/python3.9/site-packages/django/db/backends/sqlite3/base.py", line 423, in execute
    return Database.Cursor.execute(self, query, params)
sqlite3.OperationalError: no such table: django_site

The above exception was the direct cause of the following exception:

Traceback (most recent call last):
  File "/usr/local/lib/python3.9/site-packages/django/core/handlers/exception.py", line 47, in inner
    response = get_response(request)
  File "/usr/local/lib/python3.9/site-packages/django/core/handlers/base.py", line 181, in _get_response
    response = wrapped_callback(request, *callback_args, **callback_kwargs)
  File "/usr/local/lib/python3.9/site-packages/django/views/generic/base.py", line 70, in view
    return self.dispatch(request, *args, **kwargs)
  File "/usr/local/lib/python3.9/site-packages/django/utils/decorators.py", line 43, in _wrapper
    return bound_method(*args, **kwargs)
  File "/usr/local/lib/python3.9/site-packages/django/views/decorators/debug.py", line 89, in sensitive_post_parameters_wrapper
    return view(request, *args, **kwargs)
  File "/usr/local/lib/python3.9/site-packages/allauth/account/views.py", line 146, in dispatch
    return super(LoginView, self).dispatch(request, *args, **kwargs)
  File "/usr/local/lib/python3.9/site-packages/allauth/account/views.py", line 74, in dispatch
    response = super(RedirectAuthenticatedUserMixin, self).dispatch(
  File "/usr/local/lib/python3.9/site-packages/django/views/generic/base.py", line 98, in dispatch
    return handler(request, *args, **kwargs)
  File "/usr/local/lib/python3.9/site-packages/allauth/account/views.py", line 90, in get
    response = super(AjaxCapableProcessFormViewMixin, self).get(
  File "/usr/local/lib/python3.9/site-packages/django/views/generic/edit.py", line 133, in get
    return self.render_to_response(self.get_context_data())
  File "/usr/local/lib/python3.9/site-packages/allauth/account/views.py", line 177, in get_context_data
    site = get_current_site(self.request)
  File "/usr/local/lib/python3.9/site-packages/django/contrib/sites/shortcuts.py", line 13, in get_current_site
    return Site.objects.get_current(request)
  File "/usr/local/lib/python3.9/site-packages/django/contrib/sites/models.py", line 58, in get_current
    return self._get_site_by_id(site_id)
  File "/usr/local/lib/python3.9/site-packages/django/contrib/sites/models.py", line 30, in _get_site_by_id
    site = self.get(pk=site_id)
  File "/usr/local/lib/python3.9/site-packages/django/db/models/manager.py", line 85, in manager_method
    return getattr(self.get_queryset(), name)(*args, **kwargs)
  File "/usr/local/lib/python3.9/site-packages/django/db/models/query.py", line 431, in get
    num = len(clone)
  File "/usr/local/lib/python3.9/site-packages/django/db/models/query.py", line 262, in __len__
    self._fetch_all()
  File "/usr/local/lib/python3.9/site-packages/django/db/models/query.py", line 1324, in _fetch_all
    self._result_cache = list(self._iterable_class(self))
  File "/usr/local/lib/python3.9/site-packages/django/db/models/query.py", line 51, in __iter__
    results = compiler.execute_sql(chunked_fetch=self.chunked_fetch, chunk_size=self.chunk_size)
  File "/usr/local/lib/python3.9/site-packages/django/db/models/sql/compiler.py", line 1169, in execute_sql
    cursor.execute(sql, params)
  File "/usr/local/lib/python3.9/site-packages/django/db/backends/utils.py", line 98, in execute
    return super().execute(sql, params)
  File "/usr/local/lib/python3.9/site-packages/django/db/backends/utils.py", line 66, in execute
    return self._execute_with_wrappers(sql, params, many=False, executor=self._execute)
  File "/usr/local/lib/python3.9/site-packages/django/db/backends/utils.py", line 75, in _execute_with_wrappers
    return executor(sql, params, many, context)
  File "/usr/local/lib/python3.9/site-packages/django/db/backends/utils.py", line 84, in _execute
    return self.cursor.execute(sql, params)
  File "/usr/local/lib/python3.9/site-packages/django/db/utils.py", line 90, in __exit__
    raise dj_exc_value.with_traceback(traceback) from exc_value
  File "/usr/local/lib/python3.9/site-packages/django/db/backends/utils.py", line 84, in _execute
    return self.cursor.execute(sql, params)
  File "/usr/local/lib/python3.9/site-packages/django/db/backends/sqlite3/base.py", line 423, in execute
    return Database.Cursor.execute(self, query, params)
django.db.utils.OperationalError: no such table: django_site
[15/Apr/2021 10:49:26] ERROR [django.request:224] Internal Server Error: /accounts/login/
Traceback (most recent call last):
  File "/usr/local/lib/python3.9/site-packages/django/db/backends/utils.py", line 84, in _execute
    return self.cursor.execute(sql, params)
  File "/usr/local/lib/python3.9/site-packages/django/db/backends/sqlite3/base.py", line 423, in execute
    return Database.Cursor.execute(self, query, params)
sqlite3.OperationalError: no such table: django_site

The above exception was the direct cause of the following exception:

Traceback (most recent call last):
  File "/usr/local/lib/python3.9/site-packages/django/core/handlers/exception.py", line 47, in inner
    response = get_response(request)
  File "/usr/local/lib/python3.9/site-packages/django/core/handlers/base.py", line 181, in _get_response
    response = wrapped_callback(request, *callback_args, **callback_kwargs)
  File "/usr/local/lib/python3.9/site-packages/django/views/generic/base.py", line 70, in view
    return self.dispatch(request, *args, **kwargs)
  File "/usr/local/lib/python3.9/site-packages/django/utils/decorators.py", line 43, in _wrapper
    return bound_method(*args, **kwargs)
  File "/usr/local/lib/python3.9/site-packages/django/views/decorators/debug.py", line 89, in sensitive_post_parameters_wrapper
    return view(request, *args, **kwargs)
  File "/usr/local/lib/python3.9/site-packages/allauth/account/views.py", line 146, in dispatch
    return super(LoginView, self).dispatch(request, *args, **kwargs)
  File "/usr/local/lib/python3.9/site-packages/allauth/account/views.py", line 74, in dispatch
    response = super(RedirectAuthenticatedUserMixin, self).dispatch(
  File "/usr/local/lib/python3.9/site-packages/django/views/generic/base.py", line 98, in dispatch
    return handler(request, *args, **kwargs)
  File "/usr/local/lib/python3.9/site-packages/allauth/account/views.py", line 90, in get
    response = super(AjaxCapableProcessFormViewMixin, self).get(
  File "/usr/local/lib/python3.9/site-packages/django/views/generic/edit.py", line 133, in get
    return self.render_to_response(self.get_context_data())
  File "/usr/local/lib/python3.9/site-packages/allauth/account/views.py", line 177, in get_context_data
    site = get_current_site(self.request)
  File "/usr/local/lib/python3.9/site-packages/django/contrib/sites/shortcuts.py", line 13, in get_current_site
    return Site.objects.get_current(request)
  File "/usr/local/lib/python3.9/site-packages/django/contrib/sites/models.py", line 58, in get_current
    return self._get_site_by_id(site_id)
  File "/usr/local/lib/python3.9/site-packages/django/contrib/sites/models.py", line 30, in _get_site_by_id
    site = self.get(pk=site_id)
  File "/usr/local/lib/python3.9/site-packages/django/db/models/manager.py", line 85, in manager_method
    return getattr(self.get_queryset(), name)(*args, **kwargs)
  File "/usr/local/lib/python3.9/site-packages/django/db/models/query.py", line 431, in get
    num = len(clone)
  File "/usr/local/lib/python3.9/site-packages/django/db/models/query.py", line 262, in __len__
    self._fetch_all()
  File "/usr/local/lib/python3.9/site-packages/django/db/models/query.py", line 1324, in _fetch_all
    self._result_cache = list(self._iterable_class(self))
  File "/usr/local/lib/python3.9/site-packages/django/db/models/query.py", line 51, in __iter__
    results = compiler.execute_sql(chunked_fetch=self.chunked_fetch, chunk_size=self.chunk_size)
  File "/usr/local/lib/python3.9/site-packages/django/db/models/sql/compiler.py", line 1169, in execute_sql
    cursor.execute(sql, params)
  File "/usr/local/lib/python3.9/site-packages/django/db/backends/utils.py", line 98, in execute
    return super().execute(sql, params)
  File "/usr/local/lib/python3.9/site-packages/django/db/backends/utils.py", line 66, in execute
    return self._execute_with_wrappers(sql, params, many=False, executor=self._execute)
  File "/usr/local/lib/python3.9/site-packages/django/db/backends/utils.py", line 75, in _execute_with_wrappers
    return executor(sql, params, many, context)
  File "/usr/local/lib/python3.9/site-packages/django/db/backends/utils.py", line 84, in _execute
    return self.cursor.execute(sql, params)
  File "/usr/local/lib/python3.9/site-packages/django/db/utils.py", line 90, in __exit__
    raise dj_exc_value.with_traceback(traceback) from exc_value
  File "/usr/local/lib/python3.9/site-packages/django/db/backends/utils.py", line 84, in _execute
    return self.cursor.execute(sql, params)
  File "/usr/local/lib/python3.9/site-packages/django/db/backends/sqlite3/base.py", line 423, in execute
    return Database.Cursor.execute(self, query, params)
django.db.utils.OperationalError: no such table: django_site
[15/Apr/2021 10:49:26] ERROR [django.server:161] "GET /accounts/login/ HTTP/1.1" 500 178830
[15/Apr/2021 10:49:26] ERROR [django.server:161] "GET /accounts/login/ HTTP/1.1" 500 178830
[15/Apr/2021 10:50:30] ERROR [django.request:224] Internal Server Error: /accounts/signup/
Traceback (most recent call last):
  File "/usr/local/lib/python3.9/site-packages/django/db/backends/utils.py", line 84, in _execute
    return self.cursor.execute(sql, params)
  File "/usr/local/lib/python3.9/site-packages/django/db/backends/sqlite3/base.py", line 423, in execute
    return Database.Cursor.execute(self, query, params)
sqlite3.OperationalError: no such table: django_site

The above exception was the direct cause of the following exception:

Traceback (most recent call last):
  File "/usr/local/lib/python3.9/site-packages/django/core/handlers/exception.py", line 47, in inner
    response = get_response(request)
  File "/usr/local/lib/python3.9/site-packages/django/core/handlers/base.py", line 181, in _get_response
    response = wrapped_callback(request, *callback_args, **callback_kwargs)
  File "/usr/local/lib/python3.9/site-packages/django/views/generic/base.py", line 70, in view
    return self.dispatch(request, *args, **kwargs)
  File "/usr/local/lib/python3.9/site-packages/django/utils/decorators.py", line 43, in _wrapper
    return bound_method(*args, **kwargs)
  File "/usr/local/lib/python3.9/site-packages/django/views/decorators/debug.py", line 89, in sensitive_post_parameters_wrapper
    return view(request, *args, **kwargs)
  File "/usr/local/lib/python3.9/site-packages/allauth/account/views.py", line 230, in dispatch
    return super(SignupView, self).dispatch(request, *args, **kwargs)
  File "/usr/local/lib/python3.9/site-packages/allauth/account/views.py", line 74, in dispatch
    response = super(RedirectAuthenticatedUserMixin, self).dispatch(
  File "/usr/local/lib/python3.9/site-packages/allauth/account/views.py", line 204, in dispatch
    return super(CloseableSignupMixin, self).dispatch(request, *args, **kwargs)
  File "/usr/local/lib/python3.9/site-packages/django/views/generic/base.py", line 98, in dispatch
    return handler(request, *args, **kwargs)
  File "/usr/local/lib/python3.9/site-packages/allauth/account/views.py", line 90, in get
    response = super(AjaxCapableProcessFormViewMixin, self).get(
  File "/usr/local/lib/python3.9/site-packages/django/views/generic/edit.py", line 133, in get
    return self.render_to_response(self.get_context_data())
  File "/usr/local/lib/python3.9/site-packages/allauth/account/views.py", line 271, in get_context_data
    site = get_current_site(self.request)
  File "/usr/local/lib/python3.9/site-packages/django/contrib/sites/shortcuts.py", line 13, in get_current_site
    return Site.objects.get_current(request)
  File "/usr/local/lib/python3.9/site-packages/django/contrib/sites/models.py", line 58, in get_current
    return self._get_site_by_id(site_id)
  File "/usr/local/lib/python3.9/site-packages/django/contrib/sites/models.py", line 30, in _get_site_by_id
    site = self.get(pk=site_id)
  File "/usr/local/lib/python3.9/site-packages/django/db/models/manager.py", line 85, in manager_method
    return getattr(self.get_queryset(), name)(*args, **kwargs)
  File "/usr/local/lib/python3.9/site-packages/django/db/models/query.py", line 431, in get
    num = len(clone)
  File "/usr/local/lib/python3.9/site-packages/django/db/models/query.py", line 262, in __len__
    self._fetch_all()
  File "/usr/local/lib/python3.9/site-packages/django/db/models/query.py", line 1324, in _fetch_all
    self._result_cache = list(self._iterable_class(self))
  File "/usr/local/lib/python3.9/site-packages/django/db/models/query.py", line 51, in __iter__
    results = compiler.execute_sql(chunked_fetch=self.chunked_fetch, chunk_size=self.chunk_size)
  File "/usr/local/lib/python3.9/site-packages/django/db/models/sql/compiler.py", line 1169, in execute_sql
    cursor.execute(sql, params)
  File "/usr/local/lib/python3.9/site-packages/django/db/backends/utils.py", line 98, in execute
    return super().execute(sql, params)
  File "/usr/local/lib/python3.9/site-packages/django/db/backends/utils.py", line 66, in execute
    return self._execute_with_wrappers(sql, params, many=False, executor=self._execute)
  File "/usr/local/lib/python3.9/site-packages/django/db/backends/utils.py", line 75, in _execute_with_wrappers
    return executor(sql, params, many, context)
  File "/usr/local/lib/python3.9/site-packages/django/db/backends/utils.py", line 84, in _execute
    return self.cursor.execute(sql, params)
  File "/usr/local/lib/python3.9/site-packages/django/db/utils.py", line 90, in __exit__
    raise dj_exc_value.with_traceback(traceback) from exc_value
  File "/usr/local/lib/python3.9/site-packages/django/db/backends/utils.py", line 84, in _execute
    return self.cursor.execute(sql, params)
  File "/usr/local/lib/python3.9/site-packages/django/db/backends/sqlite3/base.py", line 423, in execute
    return Database.Cursor.execute(self, query, params)
django.db.utils.OperationalError: no such table: django_site
[15/Apr/2021 10:50:30] ERROR [django.request:224] Internal Server Error: /accounts/signup/
Traceback (most recent call last):
  File "/usr/local/lib/python3.9/site-packages/django/db/backends/utils.py", line 84, in _execute
    return self.cursor.execute(sql, params)
  File "/usr/local/lib/python3.9/site-packages/django/db/backends/sqlite3/base.py", line 423, in execute
    return Database.Cursor.execute(self, query, params)
sqlite3.OperationalError: no such table: django_site

The above exception was the direct cause of the following exception:

Traceback (most recent call last):
  File "/usr/local/lib/python3.9/site-packages/django/core/handlers/exception.py", line 47, in inner
    response = get_response(request)
  File "/usr/local/lib/python3.9/site-packages/django/core/handlers/base.py", line 181, in _get_response
    response = wrapped_callback(request, *callback_args, **callback_kwargs)
  File "/usr/local/lib/python3.9/site-packages/django/views/generic/base.py", line 70, in view
    return self.dispatch(request, *args, **kwargs)
  File "/usr/local/lib/python3.9/site-packages/django/utils/decorators.py", line 43, in _wrapper
    return bound_method(*args, **kwargs)
  File "/usr/local/lib/python3.9/site-packages/django/views/decorators/debug.py", line 89, in sensitive_post_parameters_wrapper
    return view(request, *args, **kwargs)
  File "/usr/local/lib/python3.9/site-packages/allauth/account/views.py", line 230, in dispatch
    return super(SignupView, self).dispatch(request, *args, **kwargs)
  File "/usr/local/lib/python3.9/site-packages/allauth/account/views.py", line 74, in dispatch
    response = super(RedirectAuthenticatedUserMixin, self).dispatch(
  File "/usr/local/lib/python3.9/site-packages/allauth/account/views.py", line 204, in dispatch
    return super(CloseableSignupMixin, self).dispatch(request, *args, **kwargs)
  File "/usr/local/lib/python3.9/site-packages/django/views/generic/base.py", line 98, in dispatch
    return handler(request, *args, **kwargs)
  File "/usr/local/lib/python3.9/site-packages/allauth/account/views.py", line 90, in get
    response = super(AjaxCapableProcessFormViewMixin, self).get(
  File "/usr/local/lib/python3.9/site-packages/django/views/generic/edit.py", line 133, in get
    return self.render_to_response(self.get_context_data())
  File "/usr/local/lib/python3.9/site-packages/allauth/account/views.py", line 271, in get_context_data
    site = get_current_site(self.request)
  File "/usr/local/lib/python3.9/site-packages/django/contrib/sites/shortcuts.py", line 13, in get_current_site
    return Site.objects.get_current(request)
  File "/usr/local/lib/python3.9/site-packages/django/contrib/sites/models.py", line 58, in get_current
    return self._get_site_by_id(site_id)
  File "/usr/local/lib/python3.9/site-packages/django/contrib/sites/models.py", line 30, in _get_site_by_id
    site = self.get(pk=site_id)
  File "/usr/local/lib/python3.9/site-packages/django/db/models/manager.py", line 85, in manager_method
    return getattr(self.get_queryset(), name)(*args, **kwargs)
  File "/usr/local/lib/python3.9/site-packages/django/db/models/query.py", line 431, in get
    num = len(clone)
  File "/usr/local/lib/python3.9/site-packages/django/db/models/query.py", line 262, in __len__
    self._fetch_all()
  File "/usr/local/lib/python3.9/site-packages/django/db/models/query.py", line 1324, in _fetch_all
    self._result_cache = list(self._iterable_class(self))
  File "/usr/local/lib/python3.9/site-packages/django/db/models/query.py", line 51, in __iter__
    results = compiler.execute_sql(chunked_fetch=self.chunked_fetch, chunk_size=self.chunk_size)
  File "/usr/local/lib/python3.9/site-packages/django/db/models/sql/compiler.py", line 1169, in execute_sql
    cursor.execute(sql, params)
  File "/usr/local/lib/python3.9/site-packages/django/db/backends/utils.py", line 98, in execute
    return super().execute(sql, params)
  File "/usr/local/lib/python3.9/site-packages/django/db/backends/utils.py", line 66, in execute
    return self._execute_with_wrappers(sql, params, many=False, executor=self._execute)
  File "/usr/local/lib/python3.9/site-packages/django/db/backends/utils.py", line 75, in _execute_with_wrappers
    return executor(sql, params, many, context)
  File "/usr/local/lib/python3.9/site-packages/django/db/backends/utils.py", line 84, in _execute
    return self.cursor.execute(sql, params)
  File "/usr/local/lib/python3.9/site-packages/django/db/utils.py", line 90, in __exit__
    raise dj_exc_value.with_traceback(traceback) from exc_value
  File "/usr/local/lib/python3.9/site-packages/django/db/backends/utils.py", line 84, in _execute
    return self.cursor.execute(sql, params)
  File "/usr/local/lib/python3.9/site-packages/django/db/backends/sqlite3/base.py", line 423, in execute
    return Database.Cursor.execute(self, query, params)
django.db.utils.OperationalError: no such table: django_site
[15/Apr/2021 10:50:30] ERROR [django.server:161] "GET /accounts/signup/ HTTP/1.1" 500 183876
[15/Apr/2021 10:50:30] ERROR [django.server:161] "GET /accounts/signup/ HTTP/1.1" 500 183876
